<?xml version="1.0" ?>
<robot name="spot" xmlns:xacro="http://www.ros.org/wiki/xacro">

    <!-- Add floating joints -->
    <link name="px">
    </link>

    <link name="py">
    </link>

    <link name="pz">
    </link>

    <link name="rx">
    </link>

    <link name="ry">
    </link>

    <link name="rz">
    </link>

    <joint name="px_virtual" type="prismatic">
        <origin xyz="0 0 0" rpy="0 0 0" />
        <parent link="ground" />
        <child link="px" />
    </joint>

    <joint name="py_virtual" type="prismatic">
        <origin xyz="0 0 0" rpy="0 0 0" />
        <parent link="px" />
        <child link="py" />
    </joint>

    <joint name="pz_virtual" type="prismatic">
        <origin xyz="0 0 0" rpy="0 0 0" />
        <parent link="py" />
        <child link="pz" />
    </joint>

    <joint name="rx_virtual" type="revolute">
        <origin xyz="0 0 0" rpy="0 0 0" />
        <parent link="pz" />
        <child link="rx" />
    </joint>

    <joint name="ry_virtual" type="revolute">
        <origin xyz="0 0 0" rpy="0 0 0" />
        <parent link="rx" />
        <child link="ry" />
    </joint>

    <joint name="rz_virtual" type="revolute">
        <origin xyz="0 0 0" rpy="0 0 0" />
        <parent link="ry" />
        <child link="body" />
    </joint>

    <link name="body">
        <inertial>
          <origin xyz="0 0 0" rpy="0 0 0" />
          <mass value="8" />
          <inertia ixx="0.190987333" iyy="0.830987333" izz="0.973333333" ixy="0" ixz="0" iyz="0" />
        </inertial>
        <visual>
            <geometry>
                <mesh filename="package://spot_description/meshes/body.dae" />
            </geometry>
        </visual>
        <collision>
            <geometry>
                <mesh filename="package://spot_description/meshes/body_collision.stl" />
            </geometry>
        </collision>
    </link>

    <link name="base_link"/>
    <joint name="base_link_joint" type="fixed">
        <origin xyz="0 0 0" rpy="0 0 0" />
        <parent link="body" />
        <child link="base_link" />
    </joint>

    <link name="front_rail"/>
    <joint name="front_rail_joint" type="fixed">
        <origin xyz="0.223 0 0.0805" rpy="0 0 0" />
        <parent link="body" />
        <child link="front_rail" />
    </joint>

    <link name="rear_rail"/>
    <joint name="rear_rail_joint" type="fixed">
        <origin xyz="-0.223 0 0.0805" rpy="0 0 0" />
        <parent link="body" />
        <child link="rear_rail" />
    </joint>

    <link name="front_left_hip">
        <inertial>
          <origin xyz="0 0 0" rpy="0 0 0" />
          <mass value="3" />
          <inertia ixx="0.009522" iyy="0.009522" izz="0.009522" ixy="0" ixz="0" iyz="0" />
        </inertial>
        <visual>
            <geometry>
                <mesh filename="package://spot_description/meshes/front_left_hip.dae" />
            </geometry>
        </visual>
        <collision>
            <geometry>
                <mesh filename="package://spot_description/meshes/front_left_hip_collision.stl" />
            </geometry>
        </collision>
    </link>
    <joint name="front_left_hip_x" type="revolute">
        <origin xyz="0.29785 0.05500 0.00000" rpy="0 0 0" />
        <axis xyz="1 0 0" />
        <parent link="body" />
        <child link="front_left_hip" />
        <limit effort="1000" velocity="1000.00" lower="-0.78539816339744827899" upper="0.78539816339744827899" />
    </joint>
    <link name="front_left_upper_leg">
        <inertial>
          <origin xyz="0 0 0" rpy="0 0 0" />
          <mass value="3" />
          <inertia ixx="0.04607325" iyy="0.045778651" izz="0.004907401" ixy="0" ixz="0" iyz="0" />
        </inertial>
        <visual>
            <geometry>
                <mesh filename="package://spot_description/meshes/front_left_upper_leg.dae" />
            </geometry>
        </visual>
        <collision>
            <geometry>
                <mesh filename="package://spot_description/meshes/front_left_upper_leg_collision.stl" />
            </geometry>
        </collision>
    </link>
    <joint name="front_left_hip_y" type="revolute">
        <origin xyz="0.0 0.110945 0.0" rpy="0 0 0" />
        <axis xyz="0 1 0" />
        <parent link="front_left_hip" />
        <child link="front_left_upper_leg" />
        <limit effort="1000" velocity="1000.00" lower="-0.89884456477707963539" upper="2.2951079663725435509" />
    </joint>
    <link name="front_left_lower_leg">
        <inertial>
          <origin xyz="0 0 0" rpy="0 0 0" />
          <mass value="3" />
          <inertia ixx="0.103885315" iyy="0.046776052" izz="0.059443485" ixy="0" ixz="0" iyz="0" />
        </inertial>
        <visual>
            <geometry>
                <mesh filename="package://spot_description/meshes/front_left_lower_leg.dae" />
            </geometry>
        </visual>
        <collision>
            <geometry>
                <mesh filename="package://spot_description/meshes/front_left_lower_leg_collision.stl" />
            </geometry>
        </collision>
    </link>
    <joint name="front_left_knee" type="revolute">
        <origin xyz="0.025 0.000 -0.3205" rpy="0 0 0" />
        <axis xyz="0 1 0" />
        <parent link="front_left_upper_leg" />
        <child link="front_left_lower_leg" />
        <limit effort="1000" velocity="1000.00" lower="-2.7929" upper="-0.254801" />
    </joint>
    <link name="front_right_hip">
        <inertial>
          <origin xyz="0 0 0" rpy="0 0 0" />
          <mass value="3" />
          <inertia ixx="0.009522" iyy="0.009522" izz="0.009522" ixy="0" ixz="0" iyz="0" />
        </inertial>
        <visual>
            <geometry>
                <mesh filename="package://spot_description/meshes/front_right_hip.dae" />
            </geometry>
        </visual>
        <collision>
            <geometry>
                <mesh filename="package://spot_description/meshes/front_right_hip_collision.stl" />
            </geometry>
        </collision>
    </link>
    <joint name="front_right_hip_x" type="revolute">
        <origin xyz="0.29785 -0.05500 0.00000" rpy="0 0 0" />
        <axis xyz="1 0 0" />
        <parent link="body" />
        <child link="front_right_hip" />
        <limit effort="1000" velocity="1000.00" lower="-0.78539816339744827899" upper="0.78539816339744827899" />
    </joint>
    <link name="front_right_upper_leg">
        <inertial>
          <origin xyz="0 0 0" rpy="0 0 0" />
          <mass value="3" />
          <inertia ixx="0.04607325" iyy="0.045778651" izz="0.004907401" ixy="0" ixz="0" iyz="0" />
        </inertial>
        <visual>
            <geometry>
                <mesh filename="package://spot_description/meshes/front_right_upper_leg.dae" />
            </geometry>
        </visual>
        <collision>
            <geometry>
                <mesh filename="package://spot_description/meshes/front_right_upper_leg_collision.stl" />
            </geometry>
        </collision>
    </link>
    <joint name="front_right_hip_y" type="revolute">
        <origin xyz="0.0 -0.110945 0.0" rpy="0 0 0" />
        <axis xyz="0 1 0" />
        <parent link="front_right_hip" />
        <child link="front_right_upper_leg" />
        <limit effort="1000" velocity="1000.00" lower="-0.89884456477707963539" upper="2.2951079663725435509" />
    </joint>
    <link name="front_right_lower_leg">
        <inertial>
          <origin xyz="0 0 0" rpy="0 0 0" />
          <mass value="3" />
          <inertia ixx="0.103885315" iyy="0.046776052" izz="0.059443485" ixy="0" ixz="0" iyz="0" />
        </inertial>
        <visual>
            <geometry>
                <mesh filename="package://spot_description/meshes/front_right_lower_leg.dae" />
            </geometry>
        </visual>
        <collision>
            <geometry>
                <mesh filename="package://spot_description/meshes/front_right_lower_leg_collision.stl" />
            </geometry>
        </collision>
    </link>
    <joint name="front_right_knee" type="revolute">
        <origin xyz="0.025 0.000 -0.3205" rpy="0 0 0" />
        <axis xyz="0 1 0" />
        <parent link="front_right_upper_leg" />
        <child link="front_right_lower_leg" />
        <limit effort="1000" velocity="1000.00" lower="-2.7929" upper="-0.247563" />
    </joint>
    <link name="rear_left_hip">
        <inertial>
          <origin xyz="0 0 0" rpy="0 0 0" />
          <mass value="3" />
          <inertia ixx="0.009522" iyy="0.009522" izz="0.009522" ixy="0" ixz="0" iyz="0" />
        </inertial>
        <visual>
            <geometry>
                <mesh filename="package://spot_description/meshes/rear_left_hip.dae" />
            </geometry>
        </visual>
        <collision>
            <geometry>
                <mesh filename="package://spot_description/meshes/rear_left_hip_collision.stl" />
            </geometry>
        </collision>
    </link>
    <joint name="rear_left_hip_x" type="revolute">
        <origin xyz="-0.29785 0.05500 0.00000" rpy="0 0 0" />
        <axis xyz="1 0 0" />
        <parent link="body" />
        <child link="rear_left_hip" />
        <limit effort="1000" velocity="1000.00" lower="-0.78539816339744827899" upper="0.78539816339744827899" />
    </joint>
    <link name="rear_left_upper_leg">
        <inertial>
          <origin xyz="0 0 0" rpy="0 0 0" />
          <mass value="3" />
          <inertia ixx="0.04607325" iyy="0.045778651" izz="0.004907401" ixy="0" ixz="0" iyz="0" />
        </inertial>
        <visual>
            <geometry>
                <mesh filename="package://spot_description/meshes/rear_left_upper_leg.dae" />
            </geometry>
        </visual>
        <collision>
            <geometry>
                <mesh filename="package://spot_description/meshes/rear_left_upper_leg_collision.stl" />
            </geometry>
        </collision>
    </link>
    <joint name="rear_left_hip_y" type="revolute">
        <origin xyz="0.0 0.110945 0.0" rpy="0 0 0" />
        <axis xyz="0 1 0" />
        <parent link="rear_left_hip" />
        <child link="rear_left_upper_leg" />
        <limit effort="1000" velocity="1000.00" lower="-0.89884456477707963539" upper="2.2951079663725435509" />
    </joint>
    <link name="rear_left_lower_leg">
        <inertial>
          <origin xyz="0 0 0" rpy="0 0 0" />
          <mass value="3" />
          <inertia ixx="0.103885315" iyy="0.046776052" izz="0.059443485" ixy="0" ixz="0" iyz="0" />
        </inertial>
        <visual>
            <geometry>
                <mesh filename="package://spot_description/meshes/rear_left_lower_leg.dae" />
            </geometry>
        </visual>
        <collision>
            <geometry>
                <mesh filename="package://spot_description/meshes/rear_left_lower_leg_collision.stl" />
            </geometry>
        </collision>
    </link>
    <joint name="rear_left_knee" type="revolute">
        <origin xyz="0.025 0.000 -0.3205" rpy="0 0 0" />
        <axis xyz="0 1 0" />
        <parent link="rear_left_upper_leg" />
        <child link="rear_left_lower_leg" />
        <limit effort="1000" velocity="1000.00" lower="-2.7929" upper="-0.267153" />
    </joint>
    <link name="rear_right_hip">
        <inertial>
          <origin xyz="0 0 0" rpy="0 0 0" />
          <mass value="3" />
          <inertia ixx="0.009522" iyy="0.009522" izz="0.009522" ixy="0" ixz="0" iyz="0" />
        </inertial>
        <visual>
            <geometry>
                <mesh filename="package://spot_description/meshes/rear_right_hip.dae" />
            </geometry>
        </visual>
        <collision>
            <geometry>
                <mesh filename="package://spot_description/meshes/rear_right_hip_collision.stl" />
            </geometry>
        </collision>
    </link>
    <joint name="rear_right_hip_x" type="revolute">
        <origin xyz="-0.29785 -0.05500 0.00000" rpy="0 0 0" />
        <axis xyz="1 0 0" />
        <parent link="body" />
        <child link="rear_right_hip" />
        <limit effort="1000" velocity="1000.00" lower="-0.78539816339744827899" upper="0.78539816339744827899" />
    </joint>
    <link name="rear_right_upper_leg">
        <inertial>
          <origin xyz="0 0 0" rpy="0 0 0" />
          <mass value="3" />
          <inertia ixx="0.04607325" iyy="0.045778651" izz="0.004907401" ixy="0" ixz="0" iyz="0" />
        </inertial>
        <visual>
            <geometry>
                <mesh filename="package://spot_description/meshes/rear_right_upper_leg.dae" />
            </geometry>
        </visual>
        <collision>
            <geometry>
                <mesh filename="package://spot_description/meshes/rear_right_upper_leg_collision.stl" />
            </geometry>
        </collision>
    </link>
    <joint name="rear_right_hip_y" type="revolute">
        <origin xyz="0.0 -0.110945 0.0" rpy="0 0 0" />
        <axis xyz="0 1 0" />
        <parent link="rear_right_hip" />
        <child link="rear_right_upper_leg" />
        <limit effort="1000" velocity="1000.00" lower="-0.89884456477707963539" upper="2.2951079663725435509" />
    </joint>
    <link name="rear_right_lower_leg">
        <inertial>
          <origin xyz="0 0 0" rpy="0 0 0" />
          <mass value="3" />
          <inertia ixx="0.103885315" iyy="0.046776052" izz="0.059443485" ixy="0" ixz="0" iyz="0" />
        </inertial>
        <visual>
            <geometry>
                <mesh filename="package://spot_description/meshes/rear_right_lower_leg.dae" />
            </geometry>
        </visual>
        <collision>
            <geometry>
                <mesh filename="package://spot_description/meshes/rear_right_lower_leg_collision.stl" />
            </geometry>
        </collision>
    </link>
    <joint name="rear_right_knee" type="revolute">
        <origin xyz="0.025 0.000 -0.3205" rpy="0 0 0" />
        <axis xyz="0 1 0" />
        <parent link="rear_right_upper_leg" />
        <child link="rear_right_lower_leg" />
        <limit effort="1000" velocity="1000.00" lower="-2.7929" upper="-0.257725" />
    </joint>

    <!-- Standard accessories. -->
    <xacro:include filename="$(find spot_description)/urdf/accessories.urdf.xacro" />

    <!-- Optional custom includes. -->
    <xacro:include filename="$(optenv SPOT_URDF_EXTRAS empty.urdf)" />
</robot>

